Traceback (most recent call last):
  File "/usr/local/lib/python3.10/dist-packages/jupyter_cache/executors/utils.py", line 58, in single_nb_execution
    executenb(
  File "/usr/local/lib/python3.10/dist-packages/nbclient/client.py", line 1305, in execute
    return NotebookClient(nb=nb, resources=resources, km=km, **kwargs).execute()
  File "/usr/local/lib/python3.10/dist-packages/jupyter_core/utils/__init__.py", line 166, in wrapped
    return loop.run_until_complete(inner)
  File "/usr/lib/python3.10/asyncio/base_events.py", line 649, in run_until_complete
    return future.result()
  File "/usr/local/lib/python3.10/dist-packages/nbclient/client.py", line 705, in async_execute
    await self.async_execute_cell(
  File "/usr/local/lib/python3.10/dist-packages/nbclient/client.py", line 1058, in async_execute_cell
    await self._check_raise_for_error(cell, cell_index, exec_reply)
  File "/usr/local/lib/python3.10/dist-packages/nbclient/client.py", line 914, in _check_raise_for_error
    raise CellExecutionError.from_cell_and_msg(cell, exec_reply_content)
nbclient.exceptions.CellExecutionError: An error occurred while executing the following cell:
------------------
def readDoc(story):
    with open(story, 'r') as file:
        document = file.read()
    return document

document = readDoc('/content/drive/MyDrive/prosaindata/tugas/story.txt')
print('The length of the file is:', end=' ')
print(len(document))
------------------


[0;31m[0m
[0;31mFileNotFoundError[0mTraceback (most recent call last)
[0;32m<ipython-input-10-82dd5bbe9e20>[0m in [0;36m<cell line: 6>[0;34m()[0m
[1;32m      4[0m     [0;32mreturn[0m [0mdocument[0m[0;34m[0m[0;34m[0m[0m
[1;32m      5[0m [0;34m[0m[0m
[0;32m----> 6[0;31m [0mdocument[0m [0;34m=[0m [0mreadDoc[0m[0;34m([0m[0;34m'/content/drive/MyDrive/prosaindata/tugas/story.txt'[0m[0;34m)[0m[0;34m[0m[0;34m[0m[0m
[0m[1;32m      7[0m [0mprint[0m[0;34m([0m[0;34m'The length of the file is:'[0m[0;34m,[0m [0mend[0m[0;34m=[0m[0;34m' '[0m[0;34m)[0m[0;34m[0m[0;34m[0m[0m
[1;32m      8[0m [0mprint[0m[0;34m([0m[0mlen[0m[0;34m([0m[0mdocument[0m[0;34m)[0m[0;34m)[0m[0;34m[0m[0;34m[0m[0m

[0;32m<ipython-input-10-82dd5bbe9e20>[0m in [0;36mreadDoc[0;34m(story)[0m
[1;32m      1[0m [0;32mdef[0m [0mreadDoc[0m[0;34m([0m[0mstory[0m[0;34m)[0m[0;34m:[0m[0;34m[0m[0;34m[0m[0m
[0;32m----> 2[0;31m     [0;32mwith[0m [0mopen[0m[0;34m([0m[0mstory[0m[0;34m,[0m [0;34m'r'[0m[0;34m)[0m [0;32mas[0m [0mfile[0m[0;34m:[0m[0;34m[0m[0;34m[0m[0m
[0m[1;32m      3[0m         [0mdocument[0m [0;34m=[0m [0mfile[0m[0;34m.[0m[0mread[0m[0;34m([0m[0;34m)[0m[0;34m[0m[0;34m[0m[0m
[1;32m      4[0m     [0;32mreturn[0m [0mdocument[0m[0;34m[0m[0;34m[0m[0m
[1;32m      5[0m [0;34m[0m[0m

[0;31mFileNotFoundError[0m: [Errno 2] No such file or directory: '/content/drive/MyDrive/prosaindata/tugas/story.txt'

